Workbook

Sheet targets
A1: target_names | B1: target_groups | C1: age_start | D1: age_end | E1: target_index | F1: n_cases | G1: n_total | H1: targets | I1: ci_lb | J1: ci_ub | K1: source
A2: =""&B2&"_"&E2 -> prevalence_preclin_71 | B2: prevalence_preclin | C2: 66 | D2: 76 | E2: =FLOOR(AVERAGE(C2,D2), 1) -> 71 | F2: =INDEX(bounds!$A$6:$L$1048576,MATCH(targets!$A2,bounds!$A$6:$A$1048576,0), MATCH(F$1,bounds!$6:$6,0)) -> 1 | G2: =INDEX(bounds!$A$6:$L$1048576,MATCH(targets!$A2,bounds!$A$6:$A$1048576,0), MATCH(G$1,bounds!$6:$6,0)) -> 1810 | H2: =INDEX(bounds!$A$6:$L$1048576,MATCH(targets!$A2,bounds!$A$6:$A$1048576,0), MATCH(H$1,bounds!$6:$6,0)) -> 0.00055248619 | I2: =INDEX(bounds!$A$6:$L$1048576,MATCH(targets!$A2,bounds!$A$6:$A$1048576,0), MATCH(I$1,bounds!$6:$6,0)) -> 9.7534037e-05 | J2: =INDEX(bounds!$A$6:$L$1048576,MATCH(targets!$A2,bounds!$A$6:$A$1048576,0), MATCH(J$1,bounds!$6:$6,0)) -> 0.0031229563 | K2: Suen et al. 1970
A3: =""&B3&"_"&E3 -> prevalence_preclin_80 | B3: prevalence_preclin | C3: 76 | D3: 85 | E3: =FLOOR(AVERAGE(C3,D3), 1) -> 80 | F3: =INDEX(bounds!$A$6:$L$1048576,MATCH(targets!$A3,bounds!$A$6:$A$1048576,0), MATCH(F$1,bounds!$6:$6,0)) -> 2 | G3: =INDEX(bounds!$A$6:$L$1048576,MATCH(targets!$A3,bounds!$A$6:$A$1048576,0), MATCH(G$1,bounds!$6:$6,0)) -> 1307 | H3: =INDEX(bounds!$A$6:$L$1048576,MATCH(targets!$A3,bounds!$A$6:$A$1048576,0), MATCH(H$1,bounds!$6:$6,0)) -> 0.0015302219 | I3: =INDEX(bounds!$A$6:$L$1048576,MATCH(targets!$A3,bounds!$A$6:$A$1048576,0), MATCH(I$1,bounds!$6:$6,0)) -> 0.00041974238 | J3: =INDEX(bounds!$A$6:$L$1048576,MATCH(targets!$A3,bounds!$A$6:$A$1048576,0), MATCH(J$1,bounds!$6:$6,0)) -> 0.0055622616 | K3: Suen et al. 1970
A4: =""&B4&"_"&E4 -> prevalence_preclin_90 | B4: prevalence_preclin | C4: 85 | D4: 95 | E4: =FLOOR(AVERAGE(C4,D4), 1) -> 90 | F4: =INDEX(bounds!$A$6:$L$1048576,MATCH(targets!$A4,bounds!$A$6:$A$1048576,0), MATCH(F$1,bounds!$6:$6,0)) -> 5 | G4: =INDEX(bounds!$A$6:$L$1048576,MATCH(targets!$A4,bounds!$A$6:$A$1048576,0), MATCH(G$1,bounds!$6:$6,0)) -> 418 | H4: =INDEX(bounds!$A$6:$L$1048576,MATCH(targets!$A4,bounds!$A$6:$A$1048576,0), MATCH(H$1,bounds!$6:$6,0)) -> 0.011961722 | I4: =INDEX(bounds!$A$6:$L$1048576,MATCH(targets!$A4,bounds!$A$6:$A$1048576,0), MATCH(I$1,bounds!$6:$6,0)) -> 0.0051198597 | J4: =INDEX(bounds!$A$6:$L$1048576,MATCH(targets!$A4,bounds!$A$6:$A$1048576,0), MATCH(J$1,bounds!$6:$6,0)) -> 0.027692133 | K4: Suen et al. 1970
A5: =""&B5&"_"&E5 -> incidence_clin_2 | B5: incidence_clin | C5: 0 | D5: =C6 -> 5 | E5: =FLOOR(AVERAGE(C5,D5), 1) -> 2 | F5: =INDEX(bounds!$23:$41,MATCH(targets!$A5,bounds!$A$23:$A$41,0), MATCH(F$1,bounds!$23:$23,0)) -> 10.087171 | G5: =INDEX(bounds!$23:$41,MATCH(targets!$A5,bounds!$A$23:$A$41,0), MATCH(G$1,bounds!$23:$23,0)) -> 10087171 | H5: =INDEX(bounds!$23:$41,MATCH(targets!$A5,bounds!$A$23:$A$41,0), MATCH(H$1,bounds!$23:$23,0)) -> 0.1 | I5: =INDEX(bounds!$23:$41,MATCH(targets!$A5,bounds!$A$23:$A$41,0), MATCH(I$1,bounds!$23:$23,0)) -> 0.016094566 | J5: =INDEX(bounds!$23:$41,MATCH(targets!$A5,bounds!$A$23:$A$41,0), MATCH(J$1,bounds!$23:$23,0)) -> 0.2452642 | K5: SEER Cancer Statistics Review 1973-1994
A6: =""&B6&"_"&E6 -> incidence_clin_7 | B6: incidence_clin | C6: 5 | D6: =C7 -> 10 | E6: =FLOOR(AVERAGE(C6,D6), 1) -> 7 | F6: =INDEX(bounds!$23:$41,MATCH(targets!$A6,bounds!$A$23:$A$41,0), MATCH(F$1,bounds!$23:$23,0)) -> 11.734749 | G6: =INDEX(bounds!$23:$41,MATCH(targets!$A6,bounds!$A$23:$A$41,0), MATCH(G$1,bounds!$23:$23,0)) -> 11734749 | H6: =INDEX(bounds!$23:$41,MATCH(targets!$A6,bounds!$A$23:$A$41,0), MATCH(H$1,bounds!$23:$23,0)) -> 0.1 | I6: =INDEX(bounds!$23:$41,MATCH(targets!$A6,bounds!$A$23:$A$41,0), MATCH(I$1,bounds!$23:$23,0)) -> 0.01625833 | J6: =INDEX(bounds!$23:$41,MATCH(targets!$A6,bounds!$A$23:$A$41,0), MATCH(J$1,bounds!$23:$23,0)) -> 0.23719287 | K6: SEER Cancer Statistics Review 1973-1994
A7: =""&B7&"_"&E7 -> incidence_clin_12 | B7: incidence_clin | C7: 10 | D7: =C8 -> 15 | E7: =FLOOR(AVERAGE(C7,D7), 1) -> 12 | F7: =INDEX(bounds!$23:$41,MATCH(targets!$A7,bounds!$A$23:$A$41,0), MATCH(F$1,bounds!$23:$23,0)) -> 0 | G7: =INDEX(bounds!$23:$41,MATCH(targets!$A7,bounds!$A$23:$A$41,0), MATCH(G$1,bounds!$23:$23,0)) -> 12224672 | H7: =INDEX(bounds!$23:$41,MATCH(targets!$A7,bounds!$A$23:$A$41,0), MATCH(H$1,bounds!$23:$23,0)) -> 0 | I7: =INDEX(bounds!$23:$41,MATCH(targets!$A7,bounds!$A$23:$A$41,0), MATCH(I$1,bounds!$23:$23,0)) -> 0 | J7: =INDEX(bounds!$23:$41,MATCH(targets!$A7,bounds!$A$23:$A$41,0), MATCH(J$1,bounds!$23:$23,0)) -> 0.10682883 | K7: SEER Cancer Statistics Review 1973-1994
A8: =""&B8&"_"&E8 -> incidence_clin_17 | B8: incidence_clin | C8: 15 | D8: =C9 -> 20 | E8: =FLOOR(AVERAGE(C8,D8), 1) -> 17 | F8: =INDEX(bounds!$23:$41,MATCH(targets!$A8,bounds!$A$23:$A$41,0), MATCH(F$1,bounds!$23:$23,0)) -> 11.213876 | G8: =INDEX(bounds!$23:$41,MATCH(targets!$A8,bounds!$A$23:$A$41,0), MATCH(G$1,bounds!$23:$23,0)) -> 11213876 | H8: =INDEX(bounds!$23:$41,MATCH(targets!$A8,bounds!$A$23:$A$41,0), MATCH(H$1,bounds!$23:$23,0)) -> 0.1 | I8: =INDEX(bounds!$23:$41,MATCH(targets!$A8,bounds!$A$23:$A$41,0), MATCH(I$1,bounds!$23:$23,0)) -> 0.017013512 | J8: =INDEX(bounds!$23:$41,MATCH(targets!$A8,bounds!$A$23:$A$41,0), MATCH(J$1,bounds!$23:$23,0)) -> 0.23722105 | K8: SEER Cancer Statistics Review 1973-1994
A9: =""&B9&"_"&E9 -> incidence_clin_22 | B9: incidence_clin | C9: 20 | D9: =C10 -> 25 | E9: =FLOOR(AVERAGE(C9,D9), 1) -> 22 | F9: =INDEX(bounds!$23:$41,MATCH(targets!$A9,bounds!$A$23:$A$41,0), MATCH(F$1,bounds!$23:$23,0)) -> 28.879569 | G9: =INDEX(bounds!$23:$41,MATCH(targets!$A9,bounds!$A$23:$A$41,0), MATCH(G$1,bounds!$23:$23,0)) -> 9626523.1 | H9: =INDEX(bounds!$23:$41,MATCH(targets!$A9,bounds!$A$23:$A$41,0), MATCH(H$1,bounds!$23:$23,0)) -> 0.3 | I9: =INDEX(bounds!$23:$41,MATCH(targets!$A9,bounds!$A$23:$A$41,0), MATCH(I$1,bounds!$23:$23,0)) -> 0.15973839 | J9: =INDEX(bounds!$23:$41,MATCH(targets!$A9,bounds!$A$23:$A$41,0), MATCH(J$1,bounds!$23:$23,0)) -> 0.48748894 | K9: SEER Cancer Statistics Review 1973-1994
A10: =""&B10&"_"&E10 -> incidence_clin_27 | B10: incidence_clin | C10: 25 | D10: =C11 -> 30 | E10: =FLOOR(AVERAGE(C10,D10), 1) -> 27 | F10: =INDEX(bounds!$23:$41,MATCH(targets!$A10,bounds!$A$23:$A$41,0), MATCH(F$1,bounds!$23:$23,0)) -> 39.624074 | G10: =INDEX(bounds!$23:$41,MATCH(targets!$A10,bounds!$A$23:$A$41,0), MATCH(G$1,bounds!$23:$23,0)) -> 7924814.9 | H10: =INDEX(bounds!$23:$41,MATCH(targets!$A10,bounds!$A$23:$A$41,0), MATCH(H$1,bounds!$23:$23,0)) -> 0.5 | I10: =INDEX(bounds!$23:$41,MATCH(targets!$A10,bounds!$A$23:$A$41,0), MATCH(I$1,bounds!$23:$23,0)) -> 0.31289158 | J10: =INDEX(bounds!$23:$41,MATCH(targets!$A10,bounds!$A$23:$A$41,0), MATCH(J$1,bounds!$23:$23,0)) -> 0.73811869 | K10: SEER Cancer Statistics Review 1973-1994
A11: =""&B11&"_"&E11 -> incidence_clin_32 | B11: incidence_clin | C11: 30 | D11: =C12 -> 35 | E11: =FLOOR(AVERAGE(C11,D11), 1) -> 32 | F11: =INDEX(bounds!$23:$41,MATCH(targets!$A11,bounds!$A$23:$A$41,0), MATCH(F$1,bounds!$23:$23,0)) -> 73.935344 | G11: =INDEX(bounds!$23:$41,MATCH(targets!$A11,bounds!$A$23:$A$41,0), MATCH(G$1,bounds!$23:$23,0)) -> 6721394.9 | H11: =INDEX(bounds!$23:$41,MATCH(targets!$A11,bounds!$A$23:$A$41,0), MATCH(H$1,bounds!$23:$23,0)) -> 1.1 | I11: =INDEX(bounds!$23:$41,MATCH(targets!$A11,bounds!$A$23:$A$41,0), MATCH(I$1,bounds!$23:$23,0)) -> 0.81842993 | J11: =INDEX(bounds!$23:$41,MATCH(targets!$A11,bounds!$A$23:$A$41,0), MATCH(J$1,bounds!$23:$23,0)) -> 1.4317979 | K11: SEER Cancer Statistics Review 1973-1994
A12: =""&B12&"_"&E12 -> incidence_clin_37 | B12: incidence_clin | C12: 35 | D12: =C13 -> 40 | E12: =FLOOR(AVERAGE(C12,D12), 1) -> 37 | F12: =INDEX(bounds!$23:$41,MATCH(targets!$A12,bounds!$A$23:$A$41,0), MATCH(F$1,bounds!$23:$23,0)) -> 143.68292 | G12: =INDEX(bounds!$23:$41,MATCH(targets!$A12,bounds!$A$23:$A$41,0), MATCH(G$1,bounds!$23:$23,0)) -> 6531041.7 | H12: =INDEX(bounds!$23:$41,MATCH(targets!$A12,bounds!$A$23:$A$41,0), MATCH(H$1,bounds!$23:$23,0)) -> 2.2 | I12: =INDEX(bounds!$23:$41,MATCH(targets!$A12,bounds!$A$23:$A$41,0), MATCH(I$1,bounds!$23:$23,0)) -> 1.8032433 | J12: =INDEX(bounds!$23:$41,MATCH(targets!$A12,bounds!$A$23:$A$41,0), MATCH(J$1,bounds!$23:$23,0)) -> 2.6371939 | K12: SEER Cancer Statistics Review 1973-1994
A13: =""&B13&"_"&E13 -> incidence_clin_42 | B13: incidence_clin | C13: 40 | D13: =C14 -> 45 | E13: =FLOOR(AVERAGE(C13,D13), 1) -> 42 | F13: =INDEX(bounds!$23:$41,MATCH(targets!$A13,bounds!$A$23:$A$41,0), MATCH(F$1,bounds!$23:$23,0)) -> 302.93943 | G13: =INDEX(bounds!$23:$41,MATCH(targets!$A13,bounds!$A$23:$A$41,0), MATCH(G$1,bounds!$23:$23,0)) -> 7045103.1 | H13: =INDEX(bounds!$23:$41,MATCH(targets!$A13,bounds!$A$23:$A$41,0), MATCH(H$1,bounds!$23:$23,0)) -> 4.3 | I13: =INDEX(bounds!$23:$41,MATCH(targets!$A13,bounds!$A$23:$A$41,0), MATCH(I$1,bounds!$23:$23,0)) -> 3.7766079 | J13: =INDEX(bounds!$23:$41,MATCH(targets!$A13,bounds!$A$23:$A$41,0), MATCH(J$1,bounds!$23:$23,0)) -> 4.8583883 | K13: SEER Cancer Statistics Review 1973-1994
A14: =""&B14&"_"&E14 -> incidence_clin_47 | B14: incidence_clin | C14: 45 | D14: =C15 -> 50 | E14: =FLOOR(AVERAGE(C14,D14), 1) -> 47 | F14: =INDEX(bounds!$23:$41,MATCH(targets!$A14,bounds!$A$23:$A$41,0), MATCH(F$1,bounds!$23:$23,0)) -> 676.82245 | G14: =INDEX(bounds!$23:$41,MATCH(targets!$A14,bounds!$A$23:$A$41,0), MATCH(G$1,bounds!$23:$23,0)) -> 7124446.8 | H14: =INDEX(bounds!$23:$41,MATCH(targets!$A14,bounds!$A$23:$A$41,0), MATCH(H$1,bounds!$23:$23,0)) -> 9.5 | I14: =INDEX(bounds!$23:$41,MATCH(targets!$A14,bounds!$A$23:$A$41,0), MATCH(I$1,bounds!$23:$23,0)) -> 8.7460519 | J14: =INDEX(bounds!$23:$41,MATCH(targets!$A14,bounds!$A$23:$A$41,0), MATCH(J$1,bounds!$23:$23,0)) -> 10.289748 | K14: SEER Cancer Statistics Review 1973-1994
A15: =""&B15&"_"&E15 -> incidence_clin_52 | B15: incidence_clin | C15: 50 | D15: =C16 -> 55 | E15: =FLOOR(AVERAGE(C15,D15), 1) -> 52 | F15: =INDEX(bounds!$23:$41,MATCH(targets!$A15,bounds!$A$23:$A$41,0), MATCH(F$1,bounds!$23:$23,0)) -> 1207.9553 | G15: =INDEX(bounds!$23:$41,MATCH(targets!$A15,bounds!$A$23:$A$41,0), MATCH(G$1,bounds!$23:$23,0)) -> 6529488.2 | H15: =INDEX(bounds!$23:$41,MATCH(targets!$A15,bounds!$A$23:$A$41,0), MATCH(H$1,bounds!$23:$23,0)) -> 18.5 | I15: =INDEX(bounds!$23:$41,MATCH(targets!$A15,bounds!$A$23:$A$41,0), MATCH(I$1,bounds!$23:$23,0)) -> 17.419891 | J15: =INDEX(bounds!$23:$41,MATCH(targets!$A15,bounds!$A$23:$A$41,0), MATCH(J$1,bounds!$23:$23,0)) -> 19.621384 | K15: SEER Cancer Statistics Review 1973-1994
A16: =""&B16&"_"&E16 -> incidence_clin_57 | B16: incidence_clin | C16: 55 | D16: =C17 -> 60 | E16: =FLOOR(AVERAGE(C16,D16), 1) -> 57 | F16: =INDEX(bounds!$23:$41,MATCH(targets!$A16,bounds!$A$23:$A$41,0), MATCH(F$1,bounds!$23:$23,0)) -> 2011.4847 | G16: =INDEX(bounds!$23:$41,MATCH(targets!$A16,bounds!$A$23:$A$41,0), MATCH(G$1,bounds!$23:$23,0)) -> 5864386.9 | H16: =INDEX(bounds!$23:$41,MATCH(targets!$A16,bounds!$A$23:$A$41,0), MATCH(H$1,bounds!$23:$23,0)) -> 34.3 | I16: =INDEX(bounds!$23:$41,MATCH(targets!$A16,bounds!$A$23:$A$41,0), MATCH(I$1,bounds!$23:$23,0)) -> 32.767494 | J16: =INDEX(bounds!$23:$41,MATCH(targets!$A16,bounds!$A$23:$A$41,0), MATCH(J$1,bounds!$23:$23,0)) -> 35.876276 | K16: SEER Cancer Statistics Review 1973-1994
... A21: =""&B21&"_"&E21 -> incidence_clin_82 | B21: incidence_clin | C21: 80 | D21: =C22 -> 85 | E21: =FLOOR(AVERAGE(C21,D21), 1) -> 82 | F21: =INDEX(bounds!$23:$41,MATCH(targets!$A21,bounds!$A$23:$A$41,0), MATCH(F$1,bounds!$23:$23,0)) -> 2005.4386 | G21: =INDEX(bounds!$23:$41,MATCH(targets!$A21,bounds!$A$23:$A$41,0), MATCH(G$1,bounds!$23:$23,0)) -> 1343227.4 | H21: =INDEX(bounds!$23:$41,MATCH(targets!$A21,bounds!$A$23:$A$41,0), MATCH(H$1,bounds!$23:$23,0)) -> 149.3 | I21: =INDEX(bounds!$23:$41,MATCH(targets!$A21,bounds!$A$23:$A$41,0), MATCH(I$1,bounds!$23:$23,0)) -> 142.76809 | J21: =INDEX(bounds!$23:$41,MATCH(targets!$A21,bounds!$A$23:$A$41,0), MATCH(J$1,bounds!$23:$23,0)) -> 156.02337 | K21: SEER Cancer Statistics Review 1973-1994
A22: =""&B22&"_"&E22 -> incidence_clin_92 | B22: incidence_clin | C22: 85 | D22: 100 | E22: =FLOOR(AVERAGE(C22,D22), 1) -> 92 | F22: =INDEX(bounds!$23:$41,MATCH(targets!$A22,bounds!$A$23:$A$41,0), MATCH(F$1,bounds!$23:$23,0)) -> 1258.9122 | G22: =INDEX(bounds!$23:$41,MATCH(targets!$A22,bounds!$A$23:$A$41,0), MATCH(G$1,bounds!$23:$23,0)) -> 888434.84 | H22: =INDEX(bounds!$23:$41,MATCH(targets!$A22,bounds!$A$23:$A$41,0), MATCH(H$1,bounds!$23:$23,0)) -> 141.7 | I22: =INDEX(bounds!$23:$41,MATCH(targets!$A22,bounds!$A$23:$A$41,0), MATCH(I$1,bounds!$23:$23,0)) -> 133.87986 | J22: =INDEX(bounds!$23:$41,MATCH(targets!$A22,bounds!$A$23:$A$41,0), MATCH(J$1,bounds!$23:$23,0)) -> 149.75933 | K22: SEER Cancer Statistics Review 1973-1994
A23: =""&B23&"_"&E23 -> stage_distr_1 | B23: stage_distr | E23: 1 | F23: =INDEX(bounds!$A$6:$L$1048576,MATCH(targets!$A23,bounds!$A$6:$A$1048576,0), MATCH(F$1,bounds!$6:$6,0)) -> 21522.9 | G23: =INDEX(bounds!$A$6:$L$1048576,MATCH(targets!$A23,bounds!$A$6:$A$1048576,0), MATCH(G$1,bounds!$6:$6,0)) -> 27630.75 | H23: =INDEX(bounds!$A$6:$L$1048576,MATCH(targets!$A23,bounds!$A$6:$A$1048576,0), MATCH(H$1,bounds!$6:$6,0)) -> 0.77894737 | I23: =INDEX(bounds!$A$6:$L$1048576,MATCH(targets!$A23,bounds!$A$6:$A$1048576,0), MATCH(I$1,bounds!$6:$6,0)) -> 0.77401602 | J23: =INDEX(bounds!$A$6:$L$1048576,MATCH(targets!$A23,bounds!$A$6:$A$1048576,0), MATCH(J$1,bounds!$6:$6,0)) -> 0.78380116 | K23: SEER Cancer Statistics Review 1973-1994
A24: =""&B24&"_"&E24 -> stage_distr_2 | B24: stage_distr | E24: 2 | F24: =INDEX(bounds!$A$6:$L$1048576,MATCH(targets!$A24,bounds!$A$6:$A$1048576,0), MATCH(F$1,bounds!$6:$6,0)) -> 5235.3 | G24: =INDEX(bounds!$A$6:$L$1048576,MATCH(targets!$A24,bounds!$A$6:$A$1048576,0), MATCH(G$1,bounds!$6:$6,0)) -> 27630.75 | H24: =INDEX(bounds!$A$6:$L$1048576,MATCH(targets!$A24,bounds!$A$6:$A$1048576,0), MATCH(H$1,bounds!$6:$6,0)) -> 0.18947368 | I24: =INDEX(bounds!$A$6:$L$1048576,MATCH(targets!$A24,bounds!$A$6:$A$1048576,0), MATCH(I$1,bounds!$6:$6,0)) -> 0.18489625 | J24: =INDEX(bounds!$A$6:$L$1048576,MATCH(targets!$A24,bounds!$A$6:$A$1048576,0), MATCH(J$1,bounds!$6:$6,0)) -> 0.19413745 | K24: SEER Cancer Statistics Review 1973-1994
A25: =""&B25&"_"&E25 -> stage_distr_3 | B25: stage_distr | E25: 3 | F25: =INDEX(bounds!$A$6:$L$1048576,MATCH(targets!$A25,bounds!$A$6:$A$1048576,0), MATCH(F$1,bounds!$6:$6,0)) -> 872.55 | G25: =INDEX(bounds!$A$6:$L$1048576,MATCH(targets!$A25,bounds!$A$6:$A$1048576,0), MATCH(G$1,bounds!$6:$6,0)) -> 27630.75 | H25: =INDEX(bounds!$A$6:$L$1048576,MATCH(targets!$A25,bounds!$A$6:$A$1048576,0), MATCH(H$1,bounds!$6:$6,0)) -> 0.031578947 | I25: =INDEX(bounds!$A$6:$L$1048576,MATCH(targets!$A25,bounds!$A$6:$A$1048576,0), MATCH(I$1,bounds!$6:$6,0)) -> 0.029581206 | J25: =INDEX(bounds!$A$6:$L$1048576,MATCH(targets!$A25,bounds!$A$6:$A$1048576,0), MATCH(J$1,bounds!$6:$6,0)) -> 0.033706918 | K25: SEER Cancer Statistics Review 1973-1994

Sheet bounds
A1: Calculations for Wilson score confidence intervals for binomial proportion
A2: Source: https://real-statistics.com/binomial-and-related-distributions/proportion-distribution/proportion-parameter-confidence-interval/
A3: Alpha | B3: 0.05
A4: zcrit | B4: =_xlfn.NORM.S.INV(1-B3/2) -> 1.959964
A6: target_names | B6: target_groups | C6: age_start | D6: age_end | E6: target_index | F6: target_labels | G6: n_total | H6: n_cases | I6: targets | J6: u | K6: ci_lb | L6: ci_ub
A7: =B7&"_"&E7 -> prevalence_preclin_71 | B7: prevalence_preclin | C7: 66 | D7: 76 | E7: =FLOOR(AVERAGE(C7,D7), 1) -> 71 | G7: 1810 | H7: 1 | I7: =H7/G7 -> 0.00055248619 | J7: =$B$4^2/G7 -> 0.0021223529 | K7: =(I7+J7/2)/(J7+1)-$B$4/(J7+1)*SQRT(I7*(1-I7)/G7+J7/(4*G7)) -> 9.7534037e-05 | L7: =(I7+J7/2)/(J7+1)+$B$4/(J7+1)*SQRT(I7*(1-I7)/G7+J7/(4*G7)) -> 0.0031229563
A8: =B8&"_"&E8 -> prevalence_preclin_80 | B8: prevalence_preclin | C8: 76 | D8: 85 | E8: =FLOOR(AVERAGE(C8,D8), 1) -> 80 | G8: 1307 | H8: 2 | I8: =H8/G8 -> 0.0015302219 | J8: =$B$4^2/G8 -> 0.0029391422 | K8: =(I8+J8/2)/(J8+1)-$B$4/(J8+1)*SQRT(I8*(1-I8)/G8+J8/(4*G8)) -> 0.00041974238 | L8: =(I8+J8/2)/(J8+1)+$B$4/(J8+1)*SQRT(I8*(1-I8)/G8+J8/(4*G8)) -> 0.0055622616
A9: =B9&"_"&E9 -> prevalence_preclin_90 | B9: prevalence_preclin | C9: 85 | D9: 95 | E9: =FLOOR(AVERAGE(C9,D9), 1) -> 90 | G9: 418 | H9: 5 | I9: =H9/G9 -> 0.011961722 | J9: =$B$4^2/G9 -> 0.0091900929 | K9: =(I9+J9/2)/(J9+1)-$B$4/(J9+1)*SQRT(I9*(1-I9)/G9+J9/(4*G9)) -> 0.0051198597 | L9: =(I9+J9/2)/(J9+1)+$B$4/(J9+1)*SQRT(I9*(1-I9)/G9+J9/(4*G9)) -> 0.027692133
A10: =B10&"_"&E10 -> stage_distr_1 | B10: stage_distr | E10: 1 | G10: =29085*0.95 -> 27630.75 | H10: =0.74*29085 -> 21522.9 | I10: =H10/G10 -> 0.77894737 | J10: =$B$4^2/G10 -> 0.00013902839 | K10: =(I10+J10/2)/(J10+1)-$B$4/(J10+1)*SQRT(I10*(1-I10)/G10+J10/(4*G10)) -> 0.77401602 | L10: =(I10+J10/2)/(J10+1)+$B$4/(J10+1)*SQRT(I10*(1-I10)/G10+J10/(4*G10)) -> 0.78380116
A11: =B11&"_"&E11 -> stage_distr_2 | B11: stage_distr | E11: 2 | G11: =29085*0.95 -> 27630.75 | H11: =0.18*29085 -> 5235.3 | I11: =H11/G11 -> 0.18947368 | J11: =$B$4^2/G11 -> 0.00013902839 | K11: =(I11+J11/2)/(J11+1)-$B$4/(J11+1)*SQRT(I11*(1-I11)/G11+J11/(4*G11)) -> 0.18489625 | L11: =(I11+J11/2)/(J11+1)+$B$4/(J11+1)*SQRT(I11*(1-I11)/G11+J11/(4*G11)) -> 0.19413745
A12: =B12&"_"&E12 -> stage_distr_3 | B12: stage_distr | E12: 3 | G12: =29085*0.95 -> 27630.75 | H12: =0.03*29085 -> 872.55 | I12: =H12/G12 -> 0.031578947 | J12: =$B$4^2/G12 -> 0.00013902839 | K12: =(I12+J12/2)/(J12+1)-$B$4/(J12+1)*SQRT(I12*(1-I12)/G12+J12/(4*G12)) -> 0.029581206 | L12: =(I12+J12/2)/(J12+1)+$B$4/(J12+1)*SQRT(I12*(1-I12)/G12+J12/(4*G12)) -> 0.033706918
A14: SEER statistics
A15: Source: https://seer.cancer.gov/archive/csr/1973_1993/appendix.pdf and https://seer.cancer.gov/archive/csr/1973_1993/bladder.pdf
A16: US standard million population, 1970 | B16: 1000000
A17: Annual population in SEER registry averaged over 1989-93 | B17: 23898718
A18: year_start | B18: 1989
A19: year_end | B19: 1993
A20: rate_unit | B20: 100000
A21: total bladder cases in SEER registry 1989-93 | B21: 22682
D22: SEER registry total scaled by US standard population | E22: bladder cancer incidence rates (invasive and in situ) per 100,000
A23: target_names | B23: target_groups | C23: age_start | D23: age_end | E23: target_index | F23: US standard million population, 1970 | G23: n_total | H23: n_cases | I23: n_cases_lb | J23: n_cases_ub | K23: targets | L23: proportion of cases | M23: ci_lb | N23: ci_ub
A24: =B24&"_"&E24 -> incidence_clin_2 | B24: incidence_clin | C24: 0 | D24: 5 | E24: =FLOOR(AVERAGE(C24,D24), 1) -> 2 | F24: 84416 | G24: =F24/$B$16*$B$17*($B$19-$B$18+1) -> 10087171 | H24: =K24*G24/$B$20 -> 10.087171 | I24: =MAX(0, K24-0.05)*G24/$B$20 -> 5.0435854 | J24: =(K24+0.05)*G24/$B$20 -> 15.130756 | K24: 0.1 | L24: =SUM(H24:H27)/H42 -> 0.0016241209 | M24: =IFERROR(0.5*_xlfn.CHISQ.INV($B$3/2,2*I24)/$G24*$B$20, 0) -> 0.016094566 | N24: =IFERROR(0.5*_xlfn.CHISQ.INV(1-$B$3/2,2*($J24+1))/$G24*$B$20, 0) -> 0.2452642
A25: =B25&"_"&E25 -> incidence_clin_7 | B25: incidence_clin | C25: 5 | D25: =C26 -> 10 | E25: =FLOOR(AVERAGE(C25,D25), 1) -> 7 | F25: 98204 | G25: =F25/$B$16*$B$17*($B$19-$B$18+1) -> 11734749 | H25: =K25*G25/$B$20 -> 11.734749 | I25: =MAX(0, K25-0.05)*G25/$B$20 -> 5.8673743 | J25: =(K25+0.05)*G25/$B$20 -> 17.602123 | K25: 0.1 | M25: =IFERROR(0.5*_xlfn.CHISQ.INV($B$3/2,2*I25)/$G25*$B$20, 0) -> 0.01625833 | N25: =IFERROR(0.5*_xlfn.CHISQ.INV(1-$B$3/2,2*($J25+1))/$G25*$B$20, 0) -> 0.23719287
A26: =B26&"_"&E26 -> incidence_clin_12 | B26: incidence_clin | C26: 10 | D26: =C27 -> 15 | E26: =FLOOR(AVERAGE(C26,D26), 1) -> 12 | F26: 102304 | G26: =F26/$B$16*$B$17*($B$19-$B$18+1) -> 12224672 | H26: =K26*G26/$B$20 -> 0 | I26: =MAX(0, K26-0.05)*G26/$B$20 -> 0 | J26: =(K26+0.05)*G26/$B$20 -> 6.1123361 | K26: 0 | M26: =IFERROR(0.5*_xlfn.CHISQ.INV($B$3/2,2*I26)/$G26*$B$20, 0) -> 0 | N26: =IFERROR(0.5*_xlfn.CHISQ.INV(1-$B$3/2,2*($J26+1))/$G26*$B$20, 0) -> 0.10682883
A27: =B27&"_"&E27 -> incidence_clin_17 | B27: incidence_clin | C27: 15 | D27: =C28 -> 20 | E27: =FLOOR(AVERAGE(C27,D27), 1) -> 17 | F27: 93845 | G27: =F27/$B$16*$B$17*($B$19-$B$18+1) -> 11213876 | H27: =K27*G27/$B$20 -> 11.213876 | I27: =MAX(0, K27-0.05)*G27/$B$20 -> 5.606938 | J27: =(K27+0.05)*G27/$B$20 -> 16.820814 | K27: 0.1 | M27: =IFERROR(0.5*_xlfn.CHISQ.INV($B$3/2,2*I27)/$G27*$B$20, 0) -> 0.017013512 | N27: =IFERROR(0.5*_xlfn.CHISQ.INV(1-$B$3/2,2*($J27+1))/$G27*$B$20, 0) -> 0.23722105
A28: =B28&"_"&E28 -> incidence_clin_22 | B28: incidence_clin | C28: 20 | D28: =C29 -> 25 | E28: =FLOOR(AVERAGE(C28,D28), 1) -> 22 | F28: 80561 | G28: =F28/$B$16*$B$17*($B$19-$B$18+1) -> 9626523.1 | H28: =K28*G28/$B$20 -> 28.879569 | I28: =MAX(0, K28-0.05)*G28/$B$20 -> 24.066308 | J28: =(K28+0.05)*G28/$B$20 -> 33.692831 | K28: 0.3 | L28: =SUM(H28:H30)/H42 -> 0.0070026509 | M28: =IFERROR(0.5*_xlfn.CHISQ.INV($B$3/2,2*I28)/$G28*$B$20, 0) -> 0.15973839 | N28: =IFERROR(0.5*_xlfn.CHISQ.INV(1-$B$3/2,2*($J28+1))/$G28*$B$20, 0) -> 0.48748894
A29: =B29&"_"&E29 -> incidence_clin_27 | B29: incidence_clin | C29: 25 | D29: =C30 -> 30 | E29: =FLOOR(AVERAGE(C29,D29), 1) -> 27 | F29: 66320 | G29: =F29/$B$16*$B$17*($B$19-$B$18+1) -> 7924814.9 | H29: =K29*G29/$B$20 -> 39.624074 | I29: =MAX(0, K29-0.05)*G29/$B$20 -> 35.661667 | J29: =(K29+0.05)*G29/$B$20 -> 43.586482 | K29: 0.5 | M29: =IFERROR(0.5*_xlfn.CHISQ.INV($B$3/2,2*I29)/$G29*$B$20, 0) -> 0.31289158 | N29: =IFERROR(0.5*_xlfn.CHISQ.INV(1-$B$3/2,2*($J29+1))/$G29*$B$20, 0) -> 0.73811869
A30: =B30&"_"&E30 -> incidence_clin_32 | B30: incidence_clin | C30: 30 | D30: =C31 -> 35 | E30: =FLOOR(AVERAGE(C30,D30), 1) -> 32 | F30: 56249 | G30: =F30/$B$16*$B$17*($B$19-$B$18+1) -> 6721394.9 | H30: =K30*G30/$B$20 -> 73.935344 | I30: =MAX(0, K30-0.05)*G30/$B$20 -> 70.574647 | J30: =(K30+0.05)*G30/$B$20 -> 77.296042 | K30: 1.1 | M30: =IFERROR(0.5*_xlfn.CHISQ.INV($B$3/2,2*I30)/$G30*$B$20, 0) -> 0.81842993 | N30: =IFERROR(0.5*_xlfn.CHISQ.INV(1-$B$3/2,2*($J30+1))/$G30*$B$20, 0) -> 1.4317979
A31: =B31&"_"&E31 -> incidence_clin_37 | B31: incidence_clin | C31: 35 | D31: =C32 -> 40 | E31: =FLOOR(AVERAGE(C31,D31), 1) -> 37 | F31: 54656 | G31: =F31/$B$16*$B$17*($B$19-$B$18+1) -> 6531041.7 | H31: =K31*G31/$B$20 -> 143.68292 | I31: =MAX(0, K31-0.05)*G31/$B$20 -> 140.4174 | J31: =(K31+0.05)*G31/$B$20 -> 146.94844 | K31: 2.2 | L31: =SUM(H31:H32)/$H$42 -> 0.021957053 | M31: =IFERROR(0.5*_xlfn.CHISQ.INV($B$3/2,2*I31)/$G31*$B$20, 0) -> 1.8032433 | N31: =IFERROR(0.5*_xlfn.CHISQ.INV(1-$B$3/2,2*($J31+1))/$G31*$B$20, 0) -> 2.6371939
A32: =B32&"_"&E32 -> incidence_clin_42 | B32: incidence_clin | C32: 40 | D32: =C33 -> 45 | E32: =FLOOR(AVERAGE(C32,D32), 1) -> 42 | F32: 58958 | G32: =F32/$B$16*$B$17*($B$19-$B$18+1) -> 7045103.1 | H32: =K32*G32/$B$20 -> 302.93943 | I32: =MAX(0, K32-0.05)*G32/$B$20 -> 299.41688 | J32: =(K32+0.05)*G32/$B$20 -> 306.46198 | K32: 4.3 | M32: =IFERROR(0.5*_xlfn.CHISQ.INV($B$3/2,2*I32)/$G32*$B$20, 0) -> 3.7766079 | N32: =IFERROR(0.5*_xlfn.CHISQ.INV(1-$B$3/2,2*($J32+1))/$G32*$B$20, 0) -> 4.8583883
A33: =B33&"_"&E33 -> incidence_clin_47 | B33: incidence_clin | C33: 45 | D33: =C34 -> 50 | E33: =FLOOR(AVERAGE(C33,D33), 1) -> 47 | F33: 59622 | G33: =F33/$B$16*$B$17*($B$19-$B$18+1) -> 7124446.8 | H33: =K33*G33/$B$20 -> 676.82245 | I33: =MAX(0, K33-0.05)*G33/$B$20 -> 673.26022 | J33: =(K33+0.05)*G33/$B$20 -> 680.38467 | K33: 9.5 | L33: =SUM(H33:H34)/$H$42 -> 0.09266031 | M33: =IFERROR(0.5*_xlfn.CHISQ.INV($B$3/2,2*I33)/$G33*$B$20, 0) -> 8.7460519 | N33: =IFERROR(0.5*_xlfn.CHISQ.INV(1-$B$3/2,2*($J33+1))/$G33*$B$20, 0) -> 10.289748
A34: =B34&"_"&E34 -> incidence_clin_52 | B34: incidence_clin | C34: 50 | D34: =C35 -> 55 | E34: =FLOOR(AVERAGE(C34,D34), 1) -> 52 | F34: 54643 | G34: =F34/$B$16*$B$17*($B$19-$B$18+1) -> 6529488.2 | H34: =K34*G34/$B$20 -> 1207.9553 | I34: =MAX(0, K34-0.05)*G34/$B$20 -> 1204.6906 | J34: =(K34+0.05)*G34/$B$20 -> 1211.2201 | K34: 18.5 | M34: =IFERROR(0.5*_xlfn.CHISQ.INV($B$3/2,2*I34)/$G34*$B$20, 0) -> 17.419891 | N34: =IFERROR(0.5*_xlfn.CHISQ.INV(1-$B$3/2,2*($J34+1))/$G34*$B$20, 0) -> 19.621384
A35: =B35&"_"&E35 -> incidence_clin_57 | B35: incidence_clin | C35: 55 | D35: =C36 -> 60 | E35: =FLOOR(AVERAGE(C35,D35), 1) -> 57 | F35: 49077 | G35: =F35/$B$16*$B$17*($B$19-$B$18+1) -> 5864386.9 | H35: =K35*G35/$B$20 -> 2011.4847 | I35: =MAX(0, K35-0.05)*G35/$B$20 -> 2008.5525 | J35: =(K35+0.05)*G35/$B$20 -> 2014.4169 | K35: 34.3 | L35: =SUM(H35:H36)/$H$42 -> 0.23066376 | M35: =IFERROR(0.5*_xlfn.CHISQ.INV($B$3/2,2*I35)/$G35*$B$20, 0) -> 32.767494 | N35: =IFERROR(0.5*_xlfn.CHISQ.INV(1-$B$3/2,2*($J35+1))/$G35*$B$20, 0) -> 35.876276
A36: =B36&"_"&E36 -> incidence_clin_62 | B36: incidence_clin | C36: 60 | D36: =C37 -> 65 | E36: =FLOOR(AVERAGE(C36,D36), 1) -> 62 | F36: 42403 | G36: =F36/$B$16*$B$17*($B$19-$B$18+1) -> 5066886.7 | H36: =K36*G36/$B$20 -> 2680.3831 | I36: =MAX(0, K36-0.05)*G36/$B$20 -> 2677.8496 | J36: =(K36+0.05)*G36/$B$20 -> 2682.9165 | K36: 52.9 | M36: =IFERROR(0.5*_xlfn.CHISQ.INV($B$3/2,2*I36)/$G36*$B$20, 0) -> 50.860284 | N36: =IFERROR(0.5*_xlfn.CHISQ.INV(1-$B$3/2,2*($J36+1))/$G36*$B$20, 0) -> 54.983958
A37: =B37&"_"&E37 -> incidence_clin_67 | B37: incidence_clin | C37: 65 | D37: =C38 -> 70 | E37: =FLOOR(AVERAGE(C37,D37), 1) -> 67 | F37: 34406 | G37: =F37/$B$16*$B$17*($B$19-$B$18+1) -> 4111296.5 | H37: =K37*G37/$B$20 -> 3404.1535 | I37: =MAX(0, K37-0.05)*G37/$B$20 -> 3402.0978 | J37: =(K37+0.05)*G37/$B$20 -> 3406.2091 | K37: 82.8 | L37: =SUM(H37:H38)/$H$42 -> 0.33905227 | M37: =IFERROR(0.5*_xlfn.CHISQ.INV($B$3/2,2*I37)/$G37*$B$20, 0) -> 79.990143 | N37: =IFERROR(0.5*_xlfn.CHISQ.INV(1-$B$3/2,2*($J37+1))/$G37*$B$20, 0) -> 85.674832
A38: =B38&"_"&E38 -> incidence_clin_72 | B38: incidence_clin | C38: 70 | D38: =C39 -> 75 | E38: =FLOOR(AVERAGE(C38,D38), 1) -> 72 | F38: 26789 | G38: =F38/$B$16*$B$17*($B$19-$B$18+1) -> 3201113.8 | H38: =K38*G38/$B$20 -> 3492.4151 | I38: =MAX(0, K38-0.05)*G38/$B$20 -> 3490.8146 | J38: =(K38+0.05)*G38/$B$20 -> 3494.0157 | K38: 109.1 | M38: =IFERROR(0.5*_xlfn.CHISQ.INV($B$3/2,2*I38)/$G38*$B$20, 0) -> 105.4525 | N38: =IFERROR(0.5*_xlfn.CHISQ.INV(1-$B$3/2,2*($J38+1))/$G38*$B$20, 0) -> 112.82993
A39: =B39&"_"&E39 -> incidence_clin_77 | B39: incidence_clin | C39: 75 | D39: =C40 -> 80 | E39: =FLOOR(AVERAGE(C39,D39), 1) -> 77 | F39: 18871 | G39: =F39/$B$16*$B$17*($B$19-$B$18+1) -> 2254963.5 | H39: =K39*G39/$B$20 -> 2981.0618 | I39: =MAX(0, K39-0.05)*G39/$B$20 -> 2979.9343 | J39: =(K39+0.05)*G39/$B$20 -> 2982.1893 | K39: 132.2 | L39: =SUM(H39:H40)/$H$42 -> 0.24514862 | M39: =IFERROR(0.5*_xlfn.CHISQ.INV($B$3/2,2*I39)/$G39*$B$20, 0) -> 127.42849 | N39: =IFERROR(0.5*_xlfn.CHISQ.INV(1-$B$3/2,2*($J39+1))/$G39*$B$20, 0) -> 137.07499
A40: =B40&"_"&E40 -> incidence_clin_82 | B40: incidence_clin | C40: 80 | D40: =C41 -> 85 | E40: =FLOOR(AVERAGE(C40,D40), 1) -> 82 | F40: 11241 | G40: =F40/$B$16*$B$17*($B$19-$B$18+1) -> 1343227.4 | H40: =K40*G40/$B$20 -> 2005.4386 | I40: =MAX(0, K40-0.05)*G40/$B$20 -> 2004.767 | J40: =(K40+0.05)*G40/$B$20 -> 2006.1102 | K40: 149.3 | M40: =IFERROR(0.5*_xlfn.CHISQ.INV($B$3/2,2*I40)/$G40*$B$20, 0) -> 142.76809 | N40: =IFERROR(0.5*_xlfn.CHISQ.INV(1-$B$3/2,2*($J40+1))/$G40*$B$20, 0) -> 156.02337
A41: =B41&"_"&E41 -> incidence_clin_92 | B41: incidence_clin | C41: 85 | D41: 100 | E41: =FLOOR(AVERAGE(C41,D41), 1) -> 92 | F41: 7435 | G41: =F41/$B$16*$B$17*($B$19-$B$18+1) -> 888434.84 | H41: =K41*G41/$B$20 -> 1258.9122 | I41: =MAX(0, K41-0.05)*G41/$B$20 -> 1258.468 | J41: =(K41+0.05)*G41/$B$20 -> 1259.3564 | K41: 141.7 | L41: =H41/H42 -> 0.061891218 | M41: =IFERROR(0.5*_xlfn.CHISQ.INV($B$3/2,2*I41)/$G41*$B$20, 0) -> 133.87986 | N41: =IFERROR(0.5*_xlfn.CHISQ.INV(1-$B$3/2,2*($J41+1))/$G41*$B$20, 0) -> 149.75933
A42: Total | F42: =SUM(F24:F41) -> 1000000 | G42: =SUM(G24:G41) -> 1.1949359e+08 | H42: =SUM(H24:H41) -> 20340.724
...
